Workbook

Sheet Dashboard
A1: Sales Forecast Dashboard
A2: Linear trend + seasonal index model, back-tested on 6 held-out months
A4: Next 12-month forecast total | D4: Avg. monthly growth (trend) | G4: Back-test accuracy (MAPE) | J4: Strongest season
A5: =SUM(Model!J58:J69) -> 861882.16 | D5: =Model!B7 -> 704.0758 | G5: =Model!B12 -> 0.028122007 | J5: =INDEX({"Jan";"Feb";"Mar";"Apr";"May";"Jun";"Jul";"Aug";"Sep";"Oct";"Nov";"Dec"},MATCH(MAX(Model!P6:P17),Model!P6:P17,0)) -> Dec
A6: Dec 2026 through the forecast horizon | D6: per month, full-history regression slope | G6: mean absolute % error, 6-month holdout | J6: highest seasonal index month, full fit
A8: Actual vs. model fit and forecast
A29: Seasonal pattern (full-history fit)
A48: Back-test detail (held-out months)
A50: Month | B50: Actual ($) | D50: Predicted ($) | E50: Abs % Error
A51: =Model!A52 -> 45839 | B51: =Model!C52 -> 63433 | D51: =Model!I52 -> 64461.825 | E51: =Model!L52 -> 0.016219076
A52: =Model!A53 -> 45870 | B52: =Model!C53 -> 65180 | D52: =Model!I53 -> 62256.825 | E52: =Model!L53 -> 0.044847735
A53: =Model!A54 -> 45901 | B53: =Model!C54 -> 61434 | D53: =Model!I54 -> 64778.825 | E53: =Model!L54 -> 0.054445822
A54: =Model!A55 -> 45931 | B54: =Model!C55 -> 66489 | D54: =Model!I55 -> 66376.825 | E54: =Model!L55 -> 0.0016871269
A55: =Model!A56 -> 45962 | B55: =Model!C56 -> 67679 | D55: =Model!I56 -> 69454.325 | E55: =Model!L56 -> 0.026231543
A56: =Model!A57 -> 45992 | B56: =Model!C57 -> 71572 | D56: =Model!I57 -> 73382.825 | E56: =Model!L57 -> 0.025300741

Sheet Data
A1: Historical Monthly Sales
A2: Source: company sales ledger (synthetic sample data for this exercise)
A4: Month | B4: Sales ($)
A5: 44927 | B5: 41310
A6: 44958 | B6: 40187
A7: 44986 | B7: 43186
A8: 45017 | B8: 45248
A9: 45047 | B9: 45282
A10: 45078 | B10: 47302
A11: 45108 | B11: 48649
A12: 45139 | B12: 46470
A13: 45170 | B13: 48769
A14: 45200 | B14: 50961
A15: 45231 | B15: 53662
A16: 45261 | B16: 56511
... A40: 45992 | B40: 71572

Sheet Model
A1: Forecast Model — Linear Trend + Seasonal Index
A2: Additive decomposition: Forecast = Trend + Seasonal Index. Fitted twice — once on months 1-30 for an honest back-test, once on all 36 months for the live forecast.
A4: Regression coefficients | N4: Seasonal index by month
A5: Fit window | B5: Slope ($/mo) | C5: Intercept ($) | N5: Mo.# | O5: Seas idx (train) | P5: Seas idx (full)
A6: Train (months 1-30) | B6: =SLOPE(C22:C51,B22:B51) -> 674.75862 | C6: =INTERCEPT(C22:C51,B22:B51) -> 42259.175 | N6: 1 | O6: =IFERROR(AVERAGEIFS($C$22:$C$51,$D$22:$D$51,N6)-AVERAGEIFS($E$22:$E$51,$D$22:$D$51,N6),0) -> -2992.3701 | P6: =IFERROR(AVERAGEIFS($C$22:$C$57,$D$22:$D$57,N6)-AVERAGEIFS($F$22:$F$57,$D$22:$D$57,N6),0) -> -3014.6109
A7: Full history (months 1-36) | B7: =SLOPE(C22:C57,B22:B57) -> 704.0758 | C7: =INTERCEPT(C22:C57,B22:B57) -> 41900.292 | N7: 2 | O7: =IFERROR(AVERAGEIFS($C$22:$C$51,$D$22:$D$51,N7)-AVERAGEIFS($E$22:$E$51,$D$22:$D$51,N7),0) -> -4004.4621 | P7: =IFERROR(AVERAGEIFS($C$22:$C$57,$D$22:$D$57,N7)-AVERAGEIFS($F$22:$F$57,$D$22:$D$57,N7),0) -> -4056.02
N8: 3 | O8: =IFERROR(AVERAGEIFS($C$22:$C$51,$D$22:$D$51,N8)-AVERAGEIFS($E$22:$E$51,$D$22:$D$51,N8),0) -> -1656.2207 | P8: =IFERROR(AVERAGEIFS($C$22:$C$57,$D$22:$D$57,N8)-AVERAGEIFS($F$22:$F$57,$D$22:$D$57,N8),0) -> -1737.0958
A9: Back-test accuracy (months 31-36, held out) | N9: 4 | O9: =IFERROR(AVERAGEIFS($C$22:$C$51,$D$22:$D$51,N9)-AVERAGEIFS($E$22:$E$51,$D$22:$D$51,N9),0) -> -1677.9793 | P9: =IFERROR(AVERAGEIFS($C$22:$C$57,$D$22:$D$57,N9)-AVERAGEIFS($F$22:$F$57,$D$22:$D$57,N9),0) -> -1788.1716
A10: MAE ($) | B10: =SUMPRODUCT(ABS(K52:K57))/6 -> 1832.5249 | N10: 5 | O10: =IFERROR(AVERAGEIFS($C$22:$C$51,$D$22:$D$51,N10)-AVERAGEIFS($E$22:$E$51,$D$22:$D$51,N10),0) -> 518.5954 | P10: =IFERROR(AVERAGEIFS($C$22:$C$57,$D$22:$D$57,N10)-AVERAGEIFS($F$22:$F$57,$D$22:$D$57,N10),0) -> 379.08593
A11: RMSE ($) | B11: =SQRT(SUMPRODUCT((K52:K57)^2)/6) -> 2130.5216 | N11: 6 | O11: =IFERROR(AVERAGEIFS($C$22:$C$51,$D$22:$D$51,N11)-AVERAGEIFS($E$22:$E$51,$D$22:$D$51,N11),0) -> 588.50345 | P11: =IFERROR(AVERAGEIFS($C$22:$C$57,$D$22:$D$57,N11)-AVERAGEIFS($F$22:$F$57,$D$22:$D$57,N11),0) -> 419.67679
A12: MAPE (%) | B12: =SUMPRODUCT(L52:L57)/6 -> 0.028122007 | N12: 7 | O12: =IFERROR(AVERAGEIFS($C$22:$C$51,$D$22:$D$51,N12)-AVERAGEIFS($E$22:$E$51,$D$22:$D$51,N12),0) -> 1669.4632 | P12: =IFERROR(AVERAGEIFS($C$22:$C$57,$D$22:$D$57,N12)-AVERAGEIFS($F$22:$F$57,$D$22:$D$57,N12),0) -> 1000.2677
N13: 8 | O13: =IFERROR(AVERAGEIFS($C$22:$C$51,$D$22:$D$51,N13)-AVERAGEIFS($E$22:$E$51,$D$22:$D$51,N13),0) -> -1210.2954 | P13: =IFERROR(AVERAGEIFS($C$22:$C$57,$D$22:$D$57,N13)-AVERAGEIFS($F$22:$F$57,$D$22:$D$57,N13),0) -> -591.47482
N14: 9 | O14: =IFERROR(AVERAGEIFS($C$22:$C$51,$D$22:$D$51,N14)-AVERAGEIFS($E$22:$E$51,$D$22:$D$51,N14),0) -> 636.94598 | P14: =IFERROR(AVERAGEIFS($C$22:$C$57,$D$22:$D$57,N14)-AVERAGEIFS($F$22:$F$57,$D$22:$D$57,N14),0) -> -862.88396
N15: 10 | O15: =IFERROR(AVERAGEIFS($C$22:$C$51,$D$22:$D$51,N15)-AVERAGEIFS($E$22:$E$51,$D$22:$D$51,N15),0) -> 1560.1874 | P15: =IFERROR(AVERAGEIFS($C$22:$C$57,$D$22:$D$57,N15)-AVERAGEIFS($F$22:$F$57,$D$22:$D$57,N15),0) -> 1183.3736
N16: 11 | O16: =IFERROR(AVERAGEIFS($C$22:$C$51,$D$22:$D$51,N16)-AVERAGEIFS($E$22:$E$51,$D$22:$D$51,N16),0) -> 3962.9287 | P16: =IFERROR(AVERAGEIFS($C$22:$C$57,$D$22:$D$57,N16)-AVERAGEIFS($F$22:$F$57,$D$22:$D$57,N16),0) -> 2927.6311
N17: 12 | O17: =IFERROR(AVERAGEIFS($C$22:$C$51,$D$22:$D$51,N17)-AVERAGEIFS($E$22:$E$51,$D$22:$D$51,N17),0) -> 7216.6701 | P17: =IFERROR(AVERAGEIFS($C$22:$C$57,$D$22:$D$57,N17)-AVERAGEIFS($F$22:$F$57,$D$22:$D$57,N17),0) -> 6140.222
N18: Center adj. | O18: =AVERAGE(O6:O17) -> 384.33056 | P18: =AVERAGE(P6:P17) -> -1.8189894e-12
A20: Monthly model table
A21: Month | B21: t | C21: Actual ($) | D21: Mo.# | E21: Trend (train fit) | F21: Trend (full fit) | G21: Seasonal idx (train) | H21: Seasonal idx (full) | I21: Back-test pred. | J21: Forecast (production) | K21: Error | L21: Abs % Error
A22: =Data!A5 -> 44927 | B22: 1 | C22: =Data!B5 -> 41310 | D22: =MONTH(A22) -> 1 | E22: =$B$6*B22+$C$6 -> 42933.933 | F22: =$B$7*B22+$C$7 -> 42604.368 | G22: =INDEX($O$6:$O$17,MATCH(D22,$N$6:$N$17,0))-$O$18 -> -3376.7007 | H22: =INDEX($P$6:$P$17,MATCH(D22,$N$6:$N$17,0))-$P$18 -> -3014.6109 | J22: =F22+H22 -> 39589.757
A23: =Data!A6 -> 44958 | B23: 2 | C23: =Data!B6 -> 40187 | D23: =MONTH(A23) -> 2 | E23: =$B$6*B23+$C$6 -> 43608.692 | F23: =$B$7*B23+$C$7 -> 43308.444 | G23: =INDEX($O$6:$O$17,MATCH(D23,$N$6:$N$17,0))-$O$18 -> -4388.7926 | H23: =INDEX($P$6:$P$17,MATCH(D23,$N$6:$N$17,0))-$P$18 -> -4056.02 | J23: =F23+H23 -> 39252.424
A24: =Data!A7 -> 44986 | B24: 3 | C24: =Data!B7 -> 43186 | D24: =MONTH(A24) -> 3 | E24: =$B$6*B24+$C$6 -> 44283.451 | F24: =$B$7*B24+$C$7 -> 44012.519 | G24: =INDEX($O$6:$O$17,MATCH(D24,$N$6:$N$17,0))-$O$18 -> -2040.5512 | H24: =INDEX($P$6:$P$17,MATCH(D24,$N$6:$N$17,0))-$P$18 -> -1737.0958 | J24: =F24+H24 -> 42275.424
A25: =Data!A8 -> 45017 | B25: 4 | C25: =Data!B8 -> 45248 | D25: =MONTH(A25) -> 4 | E25: =$B$6*B25+$C$6 -> 44958.209 | F25: =$B$7*B25+$C$7 -> 44716.595 | G25: =INDEX($O$6:$O$17,MATCH(D25,$N$6:$N$17,0))-$O$18 -> -2062.3099 | H25: =INDEX($P$6:$P$17,MATCH(D25,$N$6:$N$17,0))-$P$18 -> -1788.1716 | J25: =F25+H25 -> 42928.424
A26: =Data!A9 -> 45047 | B26: 5 | C26: =Data!B9 -> 45282 | D26: =MONTH(A26) -> 5 | E26: =$B$6*B26+$C$6 -> 45632.968 | F26: =$B$7*B26+$C$7 -> 45420.671 | G26: =INDEX($O$6:$O$17,MATCH(D26,$N$6:$N$17,0))-$O$18 -> 134.26485 | H26: =INDEX($P$6:$P$17,MATCH(D26,$N$6:$N$17,0))-$P$18 -> 379.08593 | J26: =F26+H26 -> 45799.757
A27: =Data!A10 -> 45078 | B27: 6 | C27: =Data!B10 -> 47302 | D27: =MONTH(A27) -> 6 | E27: =$B$6*B27+$C$6 -> 46307.726 | F27: =$B$7*B27+$C$7 -> 46124.747 | G27: =INDEX($O$6:$O$17,MATCH(D27,$N$6:$N$17,0))-$O$18 -> 204.17289 | H27: =INDEX($P$6:$P$17,MATCH(D27,$N$6:$N$17,0))-$P$18 -> 419.67679 | J27: =F27+H27 -> 46544.424
A28: =Data!A11 -> 45108 | B28: 7 | C28: =Data!B11 -> 48649 | D28: =MONTH(A28) -> 7 | E28: =$B$6*B28+$C$6 -> 46982.485 | F28: =$B$7*B28+$C$7 -> 46828.823 | G28: =INDEX($O$6:$O$17,MATCH(D28,$N$6:$N$17,0))-$O$18 -> 1285.1327 | H28: =INDEX($P$6:$P$17,MATCH(D28,$N$6:$N$17,0))-$P$18 -> 1000.2677 | J28: =F28+H28 -> 47829.09
A29: =Data!A12 -> 45139 | B29: 8 | C29: =Data!B12 -> 46470 | D29: =MONTH(A29) -> 8 | E29: =$B$6*B29+$C$6 -> 47657.244 | F29: =$B$7*B29+$C$7 -> 47532.898 | G29: =INDEX($O$6:$O$17,MATCH(D29,$N$6:$N$17,0))-$O$18 -> -1594.626 | H29: =INDEX($P$6:$P$17,MATCH(D29,$N$6:$N$17,0))-$P$18 -> -591.47482 | J29: =F29+H29 -> 46941.424
A30: =Data!A13 -> 45170 | B30: 9 | C30: =Data!B13 -> 48769 | D30: =MONTH(A30) -> 9 | E30: =$B$6*B30+$C$6 -> 48332.002 | F30: =$B$7*B30+$C$7 -> 48236.974 | G30: =INDEX($O$6:$O$17,MATCH(D30,$N$6:$N$17,0))-$O$18 -> 252.61542 | H30: =INDEX($P$6:$P$17,MATCH(D30,$N$6:$N$17,0))-$P$18 -> -862.88396 | J30: =F30+H30 -> 47374.09
A31: =Data!A14 -> 45200 | B31: 10 | C31: =Data!B14 -> 50961 | D31: =MONTH(A31) -> 10 | E31: =$B$6*B31+$C$6 -> 49006.761 | F31: =$B$7*B31+$C$7 -> 48941.05 | G31: =INDEX($O$6:$O$17,MATCH(D31,$N$6:$N$17,0))-$O$18 -> 1175.8568 | H31: =INDEX($P$6:$P$17,MATCH(D31,$N$6:$N$17,0))-$P$18 -> 1183.3736 | J31: =F31+H31 -> 50124.424
A32: =Data!A15 -> 45231 | B32: 11 | C32: =Data!B15 -> 53662 | D32: =MONTH(A32) -> 11 | E32: =$B$6*B32+$C$6 -> 49681.52 | F32: =$B$7*B32+$C$7 -> 49645.126 | G32: =INDEX($O$6:$O$17,MATCH(D32,$N$6:$N$17,0))-$O$18 -> 3578.5982 | H32: =INDEX($P$6:$P$17,MATCH(D32,$N$6:$N$17,0))-$P$18 -> 2927.6311 | J32: =F32+H32 -> 52572.757
A33: =Data!A16 -> 45261 | B33: 12 | C33: =Data!B16 -> 56511 | D33: =MONTH(A33) -> 12 | E33: =$B$6*B33+$C$6 -> 50356.278 | F33: =$B$7*B33+$C$7 -> 50349.202 | G33: =INDEX($O$6:$O$17,MATCH(D33,$N$6:$N$17,0))-$O$18 -> 6832.3396 | H33: =INDEX($P$6:$P$17,MATCH(D33,$N$6:$N$17,0))-$P$18 -> 6140.222 | J33: =F33+H33 -> 56489.424
... A51: =Data!A34 -> 45809 | B51: 30 | C51: =Data!B34 -> 62442 | D51: =MONTH(A51) -> 6 | E51: =$B$6*B51+$C$6 -> 62501.933 | F51: =$B$7*B51+$C$7 -> 63022.566 | G51: =INDEX($O$6:$O$17,MATCH(D51,$N$6:$N$17,0))-$O$18 -> 204.17289 | H51: =INDEX($P$6:$P$17,MATCH(D51,$N$6:$N$17,0))-$P$18 -> 419.67679 | J51: =F51+H51 -> 63442.243
A52: =Data!A35 -> 45839 | B52: 31 | C52: =Data!B35 -> 63433 | D52: =MONTH(A52) -> 7 | E52: =$B$6*B52+$C$6 -> 63176.692 | F52: =$B$7*B52+$C$7 -> 63726.642 | G52: =INDEX($O$6:$O$17,MATCH(D52,$N$6:$N$17,0))-$O$18 -> 1285.1327 | H52: =INDEX($P$6:$P$17,MATCH(D52,$N$6:$N$17,0))-$P$18 -> 1000.2677 | I52: =E52+G52 -> 64461.825 | J52: =F52+H52 -> 64726.91 | K52: =C52-I52 -> -1028.8246 | L52: =ABS(K52)/C52 -> 0.016219076
A53: =Data!A36 -> 45870 | B53: 32 | C53: =Data!B36 -> 65180 | D53: =MONTH(A53) -> 8 | E53: =$B$6*B53+$C$6 -> 63851.451 | F53: =$B$7*B53+$C$7 -> 64430.718 | G53: =INDEX($O$6:$O$17,MATCH(D53,$N$6:$N$17,0))-$O$18 -> -1594.626 | H53: =INDEX($P$6:$P$17,MATCH(D53,$N$6:$N$17,0))-$P$18 -> -591.47482 | I53: =E53+G53 -> 62256.825 | J53: =F53+H53 -> 63839.243 | K53: =C53-I53 -> 2923.1754 | L53: =ABS(K53)/C53 -> 0.044847735
A54: =Data!A37 -> 45901 | B54: 33 | C54: =Data!B37 -> 61434 | D54: =MONTH(A54) -> 9 | E54: =$B$6*B54+$C$6 -> 64526.209 | F54: =$B$7*B54+$C$7 -> 65134.794 | G54: =INDEX($O$6:$O$17,MATCH(D54,$N$6:$N$17,0))-$O$18 -> 252.61542 | H54: =INDEX($P$6:$P$17,MATCH(D54,$N$6:$N$17,0))-$P$18 -> -862.88396 | I54: =E54+G54 -> 64778.825 | J54: =F54+H54 -> 64271.91 | K54: =C54-I54 -> -3344.8246 | L54: =ABS(K54)/C54 -> 0.054445822
A55: =Data!A38 -> 45931 | B55: 34 | C55: =Data!B38 -> 66489 | D55: =MONTH(A55) -> 10 | E55: =$B$6*B55+$C$6 -> 65200.968 | F55: =$B$7*B55+$C$7 -> 65838.869 | G55: =INDEX($O$6:$O$17,MATCH(D55,$N$6:$N$17,0))-$O$18 -> 1175.8568 | H55: =INDEX($P$6:$P$17,MATCH(D55,$N$6:$N$17,0))-$P$18 -> 1183.3736 | I55: =E55+G55 -> 66376.825 | J55: =F55+H55 -> 67022.243 | K55: =C55-I55 -> 112.17538 | L55: =ABS(K55)/C55 -> 0.0016871269
A56: =Data!A39 -> 45962 | B56: 35 | C56: =Data!B39 -> 67679 | D56: =MONTH(A56) -> 11 | E56: =$B$6*B56+$C$6 -> 65875.726 | F56: =$B$7*B56+$C$7 -> 66542.945 | G56: =INDEX($O$6:$O$17,MATCH(D56,$N$6:$N$17,0))-$O$18 -> 3578.5982 | H56: =INDEX($P$6:$P$17,MATCH(D56,$N$6:$N$17,0))-$P$18 -> 2927.6311 | I56: =E56+G56 -> 69454.325 | J56: =F56+H56 -> 69470.576 | K56: =C56-I56 -> -1775.3246 | L56: =ABS(K56)/C56 -> 0.026231543
A57: =Data!A40 -> 45992 | B57: 36 | C57: =Data!B40 -> 71572 | D57: =MONTH(A57) -> 12 | E57: =$B$6*B57+$C$6 -> 66550.485 | F57: =$B$7*B57+$C$7 -> 67247.021 | G57: =INDEX($O$6:$O$17,MATCH(D57,$N$6:$N$17,0))-$O$18 -> 6832.3396 | H57: =INDEX($P$6:$P$17,MATCH(D57,$N$6:$N$17,0))-$P$18 -> 6140.222 | I57: =E57+G57 -> 73382.825 | J57: =F57+H57 -> 73387.243 | K57: =C57-I57 -> -1810.8246 | L57: =ABS(K57)/C57 -> 0.025300741
A58: =EDATE(A57,1) -> 46023 | B58: 37 | D58: =MONTH(A58) -> 1 | E58: =$B$6*B58+$C$6 -> 67225.244 | F58: =$B$7*B58+$C$7 -> 67951.097 | G58: =INDEX($O$6:$O$17,MATCH(D58,$N$6:$N$17,0))-$O$18 -> -3376.7007 | H58: =INDEX($P$6:$P$17,MATCH(D58,$N$6:$N$17,0))-$P$18 -> -3014.6109 | J58: =F58+H58 -> 64936.486
A59: =EDATE(A58,1) -> 46054 | B59: 38 | D59: =MONTH(A59) -> 2 | E59: =$B$6*B59+$C$6 -> 67900.002 | F59: =$B$7*B59+$C$7 -> 68655.173 | G59: =INDEX($O$6:$O$17,MATCH(D59,$N$6:$N$17,0))-$O$18 -> -4388.7926 | H59: =INDEX($P$6:$P$17,MATCH(D59,$N$6:$N$17,0))-$P$18 -> -4056.02 | J59: =F59+H59 -> 64599.153
...
